Workbook
Name _l9001: #REF!
Name _l9001: #REF!
Name acciones: #REF!
Name acciones: #REF!
Name ALCANCE: #REF!
Name ALCANCE: #REF!
Name Alcance.: #REF!
Name Alcance1: #REF!
Name AMENAZAS: #REF!
Name AMENAZAS: #REF!
Name anterior: #REF!
Name AUDITOR1: #REF!
Name AUDITOR1: #REF!
Name AUDITOR2: #REF!
Name AUDITOR2: #REF!
Name CALIDAD: #REF!
Name CALIDAD: #REF!
Name ccc: #REF!
Name ccc: #REF!
Name CODIGO: #REF!
Name compefactores: #REF!
Name compefactores: #REF!
Name CONSULTOR: #REF!
Name CONSULTOR: #REF!
Name dd: #REF!
Name dd: #REF!
Name DEBILIDADES: #REF!
Name DEBILIDADES: #REF!
Name DECISIONES: #REF!
Name DEMORA1: #REF!
Name DEMORA1: #REF!
Name Dimensiones: #REF!
Name Dimensiones: #REF!
Name dos: #REF!
Name EMPRESA: #REF!
Name FECHA: #REF!
Name FECHA: #REF!
Name FORTALEZA: #REF!
Name FORTALEZA: #REF!
Name INICIO: #REF!
Name k: #REF!
Name k: #REF!
Name LIDER: #REF!
Name LIDER: #REF!
Name LISTA_PROCESOS: #REF!
Name LISTA_PROCESOS: #REF!
Name LISTADO: #REF!
Name LISTADO: #REF!
Name medios: #REF!
Name MEDIOSRECEPCION: #REF!
Name MES: #REF!
Name MES: Hoja1!$A$1:$A$13
Name N_VISITA: #REF!
Name N_VISITA: #REF!
Name NATURALEZA: #REF!
Name NIVELES: #REF!
Name nuevo: #REF!
Name OBJETIVO: #REF!
Name OBJETIVO: #REF!
Name OPRTUNIDADES: #REF!

Sheet RESUMEN
D3: 1 | AA3: 2 | AY3: 3 | BW3: 4 | CU3: 5 | DS3: 6 | EQ3: 7 | FO3: 8 | GM3: 9 | HK3: 10 | II3: 11 | JG3: 12 | KE3: 13 | LC3: 14 | MA3: 15 | MY3: 16 | NW3: 17 | OU3: 18 | PS3: 19 | QQ3: 20 | RO3: 21 | SM3: 22 | TK3: 23 | UI3: 24 | VG3: 25 | WE3: 26 | XC3: 27 | YA3: 28 | YY3: 29 | ZW3: 30 | AAU3: 31 | ABS3: 32
A4: PROYECTO | C4: Inducción y/o Reinducción HSEQ | AA4: Induccion al cargo | AY4: Inducción de Gestión Humana | BW4: Inducción Seguridad Víal | CU4: Primer Respondiente "Gente que Ayuda". | DS4: Peligros y riesgos | EQ4: Ergonomia Laboral | FO4: Gestión del Riesgo Psicosocial | GM4: Seguridad Fisica y DDHH | HK4: Conservación y Cuidado del Medio Ambiente | II4: Seguridad Víal | JG4: Sistemas Inegrados de Gestion | KE4: Orden y aseo | LC4: Estilos de Vida y Trabajo Saludable | MA4: Salud Publica | MY4: Well control | NW4: Stuckm Pipe/ Pega de Tuberías | OU4: Trabajo seguro en alturas: Jefes de área para trabajos en alturas. | PS4: Manejo defensivo | QQ4: Control del Trabajo | RO4: FASE I Ecopetrol | SM4: Curso de fomento de trabajo seguro, limpio y saludable fase II | TK4: Curso de fomento de trabajo seguro, limpio y saludable fase III | UI4: Rig Inspection (Inspección de equpos de perforación) | VG4: Rig Pass | WE4: HSEQ FRONTERA | XC4: Control del Trabajo Frontera | YA4: Entrenamiento Básico para la Brigada de Emergencias | YY4: Entrenamiento para el COPASST | ZW4: Entrenamiento para el Comité de Convivencia Laboral | AAU4: Manipulación de Alimentos | ABS4: Curso de 50 o 20 horas SG-SST
C6: EN | E6: FE | G6: MAR | I6: AB | K6: MA | M6: JU | O6: JL | Q6: AG | S6: SEP | U6: OC | W6: NO | Y6: DI | AA6: EN | AC6: FE | AE6: MAR | AG6: AB | AI6: MA | AK6: JU | AM6: JL | AO6: AG | AQ6: SEP | AS6: OC | AU6: NO | AW6: DI | AY6: EN | BA6: FE | BC6: MAR | BE6: AB | BG6: MA | BI6: JU | BK6: JL | BM6: AG | BO6: SEP | BQ6: OC | BS6: NO | BU6: DI | BW6: EN | BY6: FE | CA6: MAR | CC6: AB | CE6: MA | CG6: JU | CI6: JL | CK6: AG | CM6: SEP | CO6: OC | CQ6: NO | CS6: DI | CU6: EN | CW6: FE | CY6: MAR | DA6: AB | DC6: MA | DE6: JU | DG6: JL | DI6: AG | DK6: SEP | DM6: OC | DO6: NO | DQ6: DI | DS6: EN | DU6: FE | DW6: MAR | DY6: AB | EA6: MA | EC6: JU | EE6: JL | EG6: AG | EI6: SEP | EK6: OC | EM6: NO | EO6: DI | EQ6: EN | ES6: FE | EU6: MAR | EW6: AB | EY6: MA | FA6: JU | FC6: JL | FE6: AG | FG6: SEP | FI6: OC | FK6: NO | FM6: DI | FO6: EN | FQ6: FE | FS6: MAR | FU6: AB | FW6: MA | FY6: JU | GA6: JL | GC6: AG | GE6: SEP | GG6: OC | GI6: NO | GK6: DI | GM6: EN | GO6: FE | GQ6: MAR | GS6: AB | GU6: MA | GW6: JU | GY6: JL | HA6: AG | HC6: SEP | HE6: OC | HG6: NO | HI6: DI | HK6: EN | HM6: FE | HO6: MAR | HQ6: AB | HS6: MA | HU6: JU | HW6: JL | HY6: AG | IA6: SEP | IC6: OC | IE6: NO | IG6: DI | II6: EN | IK6: FE | IM6: MAR | IO6: AB | IQ6: MA | IS6: JU | IU6: JL | IW6: AG | IY6: SEP | JA6: OC | JC6: NO | JE6: DI | JG6: EN | JI6: FE | JK6: MAR | JM6: AB | JO6: MA | JQ6: JU | JS6: JL | JU6: AG | JW6: SEP | JY6: OC | KA6: NO | KC6: DI | KE6: EN | KG6: FE | KI6: MAR | KK6: AB | KM6: MA | KO6: JU | KQ6: JL | KS6: AG | KU6: SEP | KW6: OC | KY6: NO | LA6: DI | LC6: EN | LE6: FE | LG6: MAR | LI6: AB | LK6: MA | LM6: JU | LO6: JL | LQ6: AG | LS6: SEP | LU6: OC | LW6: NO | LY6: DI | MA6: EN | MC6: FE | ME6: MAR | MG6: AB | MI6: MA | MK6: JU | MM6: JL | MO6: AG | MQ6: SEP | MS6: OC | MU6: NO | MW6: DI | MY6: EN | NA6: FE | NC6: MAR | NE6: AB | NG6: MA | NI6: JU | NK6: JL | NM6: AG | NO6: SEP | NQ6: OC | NS6: NO | NU6: DI | NW6: EN | NY6: FE | OA6: MAR | OC6: AB | OE6: MA | OG6: JU | OI6: JL | OK6: AG | OM6: SEP | OO6: OC | OQ6: NO | OS6: DI | OU6: EN | OW6: FE | OY6: MAR | PA6: AB | PC6: MA | PE6: JU | PG6: JL | PI6: AG | PK6: SEP | PM6: OC | PO6: NO | PQ6: DI | PS6: EN | PU6: FE | PW6: MAR | PY6: AB | QA6: MA | QC6: JU | QE6: JL | QG6: AG | QI6: SEP | QK6: OC | QM6: NO | QO6: DI | QQ6: EN | QS6: FE | QU6: MAR | QW6: AB | QY6: MA | RA6: JU | RC6: JL | RE6: AG | RG6: SEP | RI6: OC | RK6: NO | RM6: DI | RO6: EN | RQ6: FE | RS6: MAR | RU6: AB | RW6: MA | RY6: JU | SA6: JL | SC6: AG | SE6: SEP | SG6: OC | SI6: NO | SK6: DI | SM6: EN | SO6: FE | SQ6: MAR | SS6: AB | SU6: MA | SW6: JU | SY6: JL | TA6: AG | TC6: SEP | TE6: OC | TG6: NO | TI6: DI | TK6: EN | TM6: FE | TO6: MAR | TQ6: AB | TS6: MA | TU6: JU | TW6: JL | TY6: AG | UA6: SEP | UC6: OC | UE6: NO | UG6: DI | UI6: EN | UK6: FE | UM6: MAR | UO6: AB | UQ6: MA | US6: JU | UU6: JL | UW6: AG | UY6: SEP | VA6: OC | VC6: NO | VE6: DI | VG6: EN | VI6: FE | VK6: MAR | VM6: AB | VO6: MA | VQ6: JU | VS6: JL | VU6: AG | VW6: SEP | VY6: OC | WA6: NO | WC6: DI | WE6: EN | WG6: FE | WI6: MAR | WK6: AB | WM6: MA | WO6: JU | WQ6: JL | WS6: AG | WU6: SEP | WW6: OC | WY6: NO | XA6: DI | XC6: EN | XE6: FE | XG6: MAR | XI6: AB | XK6: MA | XM6: JU | XO6: JL | XQ6: AG | XS6: SEP | XU6: OC | XW6: NO | XY6: DI | YA6: EN | YC6: FE | YE6: MAR | YG6: AB | YI6: MA | YK6: JU | YM6: JL | YO6: AG | YQ6: SEP | YS6: OC | YU6: NO | YW6: DI | YY6: EN | ZA6: FE | ZC6: MAR | ZE6: AB | ZG6: MA | ZI6: JU | ZK6: JL | ZM6: AG | ZO6: SEP | ZQ6: OC | ZS6: NO | ZU6: DI | ZW6: EN | ZY6: FE | AAA6: MAR | AAC6: AB | AAE6: MA | AAG6: JU | AAI6: JL | AAK6: AG | AAM6: SEP | AAO6: OC | AAQ6: NO | AAS6: DI | AAU6: EN | AAW6: FE | AAY6: MAR | ABA6: AB | ABC6: MA | ABE6: JU | ABG6: JL | ABI6: AG | ABK6: SEP | ABM6: OC | ABO6: NO | ABQ6: DI | ABS6: EN | ABU6: FE | ABW6: MAR | ABY6: AB | ACA6: MA | ACC6: JU | ACE6: JL | ACG6: AG | ACI6: SEP | ACK6: OC | ACM6: NO | ACO6: DI
C7: P | D7: E | E7: P | F7: E | G7: P | H7: E | I7: P | J7: E | K7: P | L7: E | M7: P | N7: E | O7: P | P7: E | Q7: P | R7: E | S7: P | T7: E | U7: P | V7: E | W7: P | X7: E | Y7: P | Z7: E | AA7: P | AB7: E | AC7: P | AD7: E | AE7: P | AF7: E | AG7: P | AH7: E | AI7: P | AJ7: E | AK7: P | AL7: E | AM7: P | AN7: E | AO7: P | AP7: E | AQ7: P | AR7: E | AS7: P | AT7: E | AU7: P | AV7: E | AW7: P | AX7: E | AY7: P | AZ7: E | BA7: P | BB7: E | BC7: P | BD7: E | BE7: P | BF7: E | BG7: P | BH7: E | BI7: P | BJ7: E | BK7: P | BL7: E | BM7: P | BN7: E | BO7: P | BP7: E | BQ7: P | BR7: E | BS7: P | BT7: E | BU7: P | BV7: E | BW7: P | BX7: E | BY7: P | BZ7: E | CA7: P | CB7: E | CC7: P | CD7: E | CE7: P | CF7: E | CG7: P | CH7: E | CI7: P | CJ7: E | CK7: P | CL7: E | CM7: P | CN7: E | CO7: P | CP7: E | CQ7: P | CR7: E | CS7: P | CT7: E | CU7: P | CV7: E | CW7: P | CX7: E | CY7: P | CZ7: E | DA7: P | DB7: E | DC7: P | DD7: E | DE7: P | DF7: E | DG7: P | DH7: E | DI7: P | DJ7: E | DK7: P | DL7: E | DM7: P | DN7: E | DO7: P | DP7: E | DQ7: P | DR7: E | DS7: P | DT7: E | DU7: P | DV7: E | DW7: P | DX7: E | DY7: P | DZ7: E | EA7: P | EB7: E | EC7: P | ED7: E | EE7: P | EF7: E | EG7: P | EH7: E | EI7: P | EJ7: E | EK7: P | EL7: E | EM7: P | EN7: E | EO7: P | EP7: E | EQ7: P | ER7: E | ES7: P | ET7: E | EU7: P | EV7: E | EW7: P | EX7: E | EY7: P | EZ7: E | FA7: P | FB7: E | FC7: P | FD7: E | FE7: P | FF7: E | FG7: P | FH7: E | FI7: P | FJ7: E | FK7: P | FL7: E | FM7: P | FN7: E | FO7: P | FP7: E | FQ7: P | FR7: E | FS7: P | FT7: E | FU7: P | FV7: E | FW7: P | FX7: E | FY7: P | FZ7: E | GA7: P | GB7: E | GC7: P | GD7: E | GE7: P | GF7: E | GG7: P | GH7: E | GI7: P | GJ7: E | GK7: P | GL7: E | GM7: P | GN7: E | GO7: P | GP7: E | GQ7: P | GR7: E | GS7: P | GT7: E | GU7: P | GV7: E | GW7: P | GX7: E | GY7: P | GZ7: E | HA7: P | HB7: E | HC7: P | HD7: E | HE7: P | HF7: E | HG7: P | HH7: E | HI7: P | HJ7: E | HK7: P | HL7: E | HM7: P | HN7: E | HO7: P | HP7: E | HQ7: P | HR7: E | HS7: P | HT7: E | HU7: P | HV7: E | HW7: P | HX7: E | HY7: P | HZ7: E | IA7: P | IB7: E | IC7: P | ID7: E | IE7: P | IF7: E | IG7: P | IH7: E | II7: P | IJ7: E | IK7: P | IL7: E | IM7: P | IN7: E | IO7: P | IP7: E | IQ7: P | IR7: E | IS7: P | IT7: E | IU7: P | IV7: E | IW7: P | IX7: E | IY7: P | IZ7: E | JA7: P | JB7: E | JC7: P | JD7: E | JE7: P | JF7: E | JG7: P | JH7: E | JI7: P | JJ7: E | JK7: P | JL7: E | JM7: P | JN7: E | JO7: P | JP7: E | JQ7: P | JR7: E | JS7: P | JT7: E | JU7: P | JV7: E | JW7: P | JX7: E | JY7: P | JZ7: E | KA7: P | KB7: E | KC7: P | KD7: E | KE7: P | KF7: E | KG7: P | KH7: E | KI7: P | KJ7: E | KK7: P | KL7: E | KM7: P | KN7: E | KO7: P | KP7: E | KQ7: P | KR7: E | KS7: P | KT7: E | KU7: P | KV7: E | KW7: P | KX7: E | KY7: P | KZ7: E | LA7: P | LB7: E | LC7: P | LD7: E | LE7: P | LF7: E | LG7: P | LH7: E | LI7: P | LJ7: E | LK7: P | LL7: E | LM7: P | LN7: E | LO7: P | LP7: E | LQ7: P | LR7: E | LS7: P | LT7: E | LU7: P | LV7: E | LW7: P | LX7: E | LY7: P | LZ7: E | MA7: P | MB7: E | MC7: P | MD7: E | ME7: P | MF7: E | MG7: P | MH7: E | MI7: P | MJ7: E | MK7: P | ML7: E | MM7: P | MN7: E | MO7: P | MP7: E | MQ7: P | MR7: E | MS7: P | MT7: E | MU7: P | MV7: E | MW7: P | MX7: E | MY7: P | MZ7: E | NA7: P | NB7: E | NC7: P | ND7: E | NE7: P | NF7: E | NG7: P | NH7: E | NI7: P | NJ7: E | NK7: P | NL7: E | NM7: P | NN7: E | NO7: P | NP7: E | NQ7: P | NR7: E | NS7: P | NT7: E | NU7: P | NV7: E | NW7: P | NX7: E | NY7: P | NZ7: E | OA7: P | OB7: E | OC7: P | OD7: E | OE7: P | OF7: E | OG7: P | OH7: E | OI7: P | OJ7: E | OK7: P | OL7: E | OM7: P | ON7: E | OO7: P | OP7: E | OQ7: P | OR7: E | OS7: P | OT7: E | OU7: P | OV7: E | OW7: P | OX7: E | OY7: P | OZ7: E | PA7: P | PB7: E | PC7: P | PD7: E | PE7: P | PF7: E | PG7: P | PH7: E | PI7: P | PJ7: E | PK7: P | PL7: E | PM7: P | PN7: E | PO7: P | PP7: E | PQ7: P | PR7: E | PS7: P | PT7: E | PU7: P | PV7: E | PW7: P | PX7: E | PY7: P | PZ7: E | QA7: P | QB7: E | QC7: P | QD7: E | QE7: P | QF7: E | QG7: P | QH7: E | QI7: P | QJ7: E | QK7: P | QL7: E | QM7: P | QN7: E | QO7: P | QP7: E | QQ7: P | QR7: E | QS7: P | QT7: E | QU7: P | QV7: E | QW7: P | QX7: E | QY7: P | QZ7: E | RA7: P | RB7: E | RC7: P | RD7: E | RE7: P | RF7: E | RG7: P | RH7: E | RI7: P | RJ7: E | RK7: P | RL7: E | RM7: P | RN7: E | RO7: P | RP7: E | RQ7: P | RR7: E | RS7: P | RT7: E | RU7: P | RV7: E | RW7: P | RX7: E | RY7: P | RZ7: E | SA7: P | SB7: E | SC7: P | SD7: E | SE7: P | SF7: E | SG7: P | SH7: E | SI7: P | SJ7: E | SK7: P | SL7: E | SM7: P | SN7: E | SO7: P | SP7: E | SQ7: P | SR7: E | SS7: P | ST7: E | SU7: P | SV7: E | SW7: P | SX7: E | SY7: P | SZ7: E | TA7: P | TB7: E | TC7: P | TD7: E | TE7: P | TF7: E | TG7: P | TH7: E | TI7: P | TJ7: E | TK7: P | TL7: E | TM7: P | TN7: E | TO7: P | TP7: E | TQ7: P | TR7: E | TS7: P | TT7: E | TU7: P | TV7: E | TW7: P | TX7: E | TY7: P | TZ7: E | UA7: P | UB7: E | UC7: P | UD7: E | UE7: P | UF7: E | UG7: P | UH7: E | UI7: P | UJ7: E | UK7: P | UL7: E | UM7: P | UN7: E | UO7: P | UP7: E | UQ7: P | UR7: E | US7: P | UT7: E | UU7: P | UV7: E | UW7: P | UX7: E | UY7: P | UZ7: E | VA7: P | VB7: E | VC7: P | VD7: E | VE7: P | VF7: E | VG7: P | VH7: E | VI7: P | VJ7: E | VK7: P | VL7: E | VM7: P | VN7: E | VO7: P | VP7: E | VQ7: P | VR7: E | VS7: P | VT7: E | VU7: P | VV7: E | VW7: P | VX7: E | VY7: P | VZ7: E | WA7: P | WB7: E | WC7: P | WD7: E | WE7: P | WF7: E | WG7: P | WH7: E | WI7: P | WJ7: E | WK7: P | WL7: E | WM7: P | WN7: E | WO7: P | WP7: E | WQ7: P | WR7: E | WS7: P | WT7: E | WU7: P | WV7: E | WW7: P | WX7: E | WY7: P | WZ7: E | XA7: P | XB7: E | XC7: P | XD7: E | XE7: P | XF7: E | XG7: P | XH7: E | XI7: P | XJ7: E | XK7: P | XL7: E | XM7: P | XN7: E | XO7: P | XP7: E | XQ7: P | XR7: E | XS7: P | XT7: E | XU7: P | XV7: E | XW7: P | XX7: E | XY7: P | XZ7: E | YA7: P | YB7: E | YC7: P | YD7: E | YE7: P | YF7: E | YG7: P | YH7: E | YI7: P | YJ7: E | YK7: P | YL7: E | YM7: P | YN7: E | YO7: P | YP7: E | YQ7: P | YR7: E | YS7: P | YT7: E | YU7: P | YV7: E | YW7: P | YX7: E | YY7: P | YZ7: E | ZA7: P | ZB7: E | ZC7: P | ZD7: E | ZE7: P | ZF7: E | ZG7: P | ZH7: E | ZI7: P | ZJ7: E | ZK7: P | ZL7: E | ZM7: P | ZN7: E | ZO7: P | ZP7: E | ZQ7: P | ZR7: E | ZS7: P | ZT7: E | ZU7: P | ZV7: E | ZW7: P | ZX7: E | ZY7: P | ZZ7: E | AAA7: P | AAB7: E | AAC7: P | AAD7: E | AAE7: P | AAF7: E | AAG7: P | AAH7: E | AAI7: P | AAJ7: E | AAK7: P | AAL7: E | AAM7: P | AAN7: E | AAO7: P | AAP7: E | AAQ7: P | AAR7: E | AAS7: P | AAT7: E | AAU7: P | AAV7: E | AAW7: P | AAX7: E | AAY7: P | AAZ7: E | ABA7: P | ABB7: E | ABC7: P | ABD7: E | ABE7: P | ABF7: E | ABG7: P | ABH7: E | ABI7: P | ABJ7: E | ABK7: P | ABL7: E | ABM7: P | ABN7: E | ABO7: P | ABP7: E | ABQ7: P | ABR7: E | ABS7: P | ABT7: E | ABU7: P | ABV7: E | ABW7: P | ABX7: E | ABY7: P | ABZ7: E | ACA7: P | ACB7: E | ACC7: P | ACD7: E | ACE7: P | ACF7: E | ACG7: P | ACH7: E | ACI7: P | ACJ7: E | ACK7: P | ACL7: E | ACM7: P | ACN7: E | ACO7: P | ACP7: E
A8: ADMOND | C8: =COUNTIFS(SEGUIMIENTO_PERSONAL!$J$10:$J$42,"E",SEGUIMIENTO_PERSONAL!$M$10:$M$42,"ENERO")+COUNTIFS(SEGUIMIENTO_PERSONAL!$J$10:$J$42,"P",SEGUIMIENTO_PERSONAL!$M$10:$M$42,"ENERO") -> 11 | D8: #VALUE! | E8: #VALUE! | F8: #VALUE! | G8: #VALUE! | H8: #VALUE! | I8: #VALUE! | J8: #VALUE! | K8: #VALUE! | L8: #VALUE! | M8: #VALUE! | N8: #VALUE! | O8: #VALUE! | P8: #VALUE! | Q8: #VALUE! | R8: #VALUE! | S8: #VALUE! | T8: #VALUE! | U8: #VALUE! | V8: #VALUE! | W8: #VALUE! | X8: #VALUE! | Y8: #VALUE! | Z8: #VALUE! | AA8: #VALUE! | AB8: #VALUE! | AC8: #VALUE! | AD8: #VALUE! | AE8: #VALUE! | AF8: #VALUE! | AG8: #VALUE! | AH8: #VALUE! | AI8: #VALUE! | AJ8: #VALUE! | AK8: #VALUE! | AL8: #VALUE! | AM8: #VALUE! | AN8: #VALUE! | AO8: #VALUE! | AP8: #VALUE! | AQ8: #VALUE! | AR8: #VALUE! | AS8: #VALUE! | AT8: #VALUE! | AU8: #VALUE! | AV8: #VALUE! | AW8: #VALUE! | AX8: #VALUE! | AY8: #VALUE! | AZ8: #VALUE! | BA8: #VALUE! | BB8: #VALUE! | BC8: #VALUE! | BD8: #VALUE! | BE8: #VALUE! | BF8: #VALUE! | BG8: #VALUE! | BH8: #VALUE! | BI8: #VALUE! | BJ8: #VALUE! | BK8: #VALUE! | BL8: #VALUE! | BM8: #VALUE! | BN8: #VALUE! | BO8: #VALUE! | BP8: #VALUE! | BQ8: #VALUE! | BR8: #VALUE! | BS8: #VALUE! | BT8: #VALUE! | BU8: #VALUE! | BV8: #VALUE! | BW8: #VALUE! | CU8: #VALUE! | CV8: #VALUE! | CW8: #VALUE! | CX8: #VALUE! | CY8: #VALUE! | CZ8: #VALUE! | DA8: #VALUE! | DB8: #VALUE! | DC8: #VALUE! | DD8: #VALUE! | DE8: #VALUE! | DF8: #VALUE! | DG8: #VALUE! | DH8: #VALUE! | DI8: #VALUE! | DJ8: #VALUE! | DK8: #VALUE! | DL8: #VALUE! | DM8: #VALUE! | DN8: #VALUE! | DO8: #VALUE! | DP8: #VALUE! | DQ8: #VALUE! | DR8: #VALUE! | DS8: #VALUE! | DT8: #VALUE! | DU8: #VALUE! | DV8: #VALUE! | DW8: #VALUE! | DX8: #VALUE! | DY8: #VALUE! | DZ8: #VALUE! | EA8: #VALUE! | EB8: #VALUE! | EC8: #VALUE! | ED8: #VALUE! | EE8: #VALUE! | EF8: #VALUE! | EG8: #VALUE! | EH8: #VALUE! | EI8: #VALUE! | EJ8: #VALUE! | EK8: #VALUE! | EL8: #VALUE! | EM8: #VALUE! | EN8: #VALUE! | EO8: #VALUE! | EP8: #VALUE! | EQ8: #VALUE! | ER8: #VALUE! | ES8: #VALUE! | ET8: #VALUE! | EU8: #VALUE! | EV8: #VALUE! | EW8: #VALUE! | EX8: #VALUE! | EY8: #VALUE! | EZ8: #VALUE! | FA8: #VALUE! | FB8: #VALUE! | FC8: #VALUE! | FD8: #VALUE! | FE8: #VALUE! | FF8: #VALUE! | FG8: #VALUE! | FH8: #VALUE! | FI8: #VALUE! | FJ8: #VALUE! | FK8: #VALUE! | FL8: #VALUE! | FM8: #VALUE! | FN8: #VALUE! | FO8: #VALUE! | FP8: #VALUE! | FQ8: #VALUE! | FR8: #VALUE! | FS8: #VALUE! | FT8: #VALUE! | FU8: #VALUE! | FV8: #VALUE! | FW8: #VALUE! | FX8: #VALUE! | FY8: #VALUE! | FZ8: #VALUE! | GA8: #VALUE! | GB8: #VALUE! | GC8: #VALUE! | GD8: #VALUE! | GE8: #VALUE! | GF8: #VALUE! | GG8: #VALUE! | GH8: #VALUE! | GI8: #VALUE! | GJ8: #VALUE! | GK8: #VALUE! | GL8: #VALUE! | GM8: 0 | GN8: 0 | GO8: 0 | GP8: 0 | GQ8: 0 | GR8: 0 | GS8: 0 | GT8: 0 | GU8: #VALUE! | GV8: #VALUE! | GW8: 0 | GX8: 0 | GY8: 0 | GZ8: 0 | HA8: 0 | HB8: 0 | HC8: 0 | HD8: 0 | HE8: 0 | HF8: 0 | HG8: 0 | HH8: 0 | HI8: 0 | HJ8: 0 | HK8: 0 | HL8: 0 | HM8: 0 | HN8: 0 | HO8: 0 | HP8: 0 | HQ8: 0 | HR8: 0 | HS8: #VALUE! | HT8: #VALUE! | HU8: #VALUE! | HV8: #VALUE! | HW8: 0 | HX8: 0 | HY8: 0 | HZ8: 0 | IA8: 0 | IB8: 0 | IC8: 0 | ID8: 0 | IE8: 0 | IF8: 0 | IG8: 0 | IH8: 0 | II8: 0 | IJ8: 0 | IK8: 0 | IL8: 0 | IM8: 0 | IN8: 0 | IO8: 0 | IP8: 0 | IQ8: #VALUE! | IR8: #VALUE! | IS8: 0 | IT8: #VALUE! | IU8: #VALUE! | IV8: #VALUE! | IW8: 0 | IX8: 0 | IY8: 0 | IZ8: 0 | JA8: 0 | JB8: 0 | JC8: 0 | JD8: 0 | JE8: 0 | JF8: 0 | JG8: 0 | JH8: 0 | JI8: 0 | JJ8: 0 | JK8: 0 | JL8: 0 | JM8: 0 | JN8: 0 | JO8: #VALUE! | JP8: #VALUE! | JQ8: 0 | JR8: #VALUE! | JS8: 0 | JT8: 0 | JU8: #VALUE! | JV8: #VALUE! | JW8: 0 | JX8: 0 | JY8: 0 | JZ8: 0 | KA8: 0 | KB8: 0 | KC8: 0 | KD8: 0 | KE8: 0 | KF8: 0 | KG8: 0 | KH8: 0 | KI8: 0 | KJ8: 0 | KK8: 0 | KL8: 0 | KM8: #VALUE! | KN8: #VALUE! | KO8: 0 | KP8: #VALUE! | KQ8: 0 | KR8: 0 | KS8: 0 | KT8: 0 | KU8: #VALUE! | KV8: #VALUE! | KW8: 0 | KX8: 0 | KY8: 0 | KZ8: 0 | LA8: 0 | LB8: 0 | LC8: 0 | LD8: 0 | LE8: 0 | LF8: 0 | LG8: 0 | LH8: 0 | LI8: 0 | LJ8: 0 | LK8: #VALUE! | LL8: #VALUE! | LM8: 0 | LN8: #VALUE! | LO8: 0 | LP8: 0 | LQ8: 0 | LR8: 0 | LS8: 0 | LT8: 0 | LU8: #VALUE! | LV8: #VALUE! | LW8: 0 | LX8: 0 | LY8: 0 | LZ8: 0 | MA8: 0 | MB8: 0 | MC8: 0 | MD8: 0 | ME8: 0 | MF8: 0 | MG8: 0 | MH8: 0 | MI8: #VALUE! | MJ8: #VALUE! | MK8: 0 | ML8: #VALUE! | MM8: 0 | MN8: 0 | MO8: 0 | MP8: 0 | MQ8: 0 | MR8: 0 | MS8: 0 | MT8: 0 | MU8: #VALUE! | MV8: #VALUE! | MW8: 0 | MX8: 0 | MY8: 0 | MZ8: 0 | NA8: 0 | NB8: 0 | NC8: 0 | ND8: 0 | NE8: 0 | NF8: 0 | NG8: 0 | NH8: 0 | NI8: 0 | NJ8: 0 | NK8: 0 | NL8: 0 | NM8: 0 | NN8: 0 | NO8: 0 | NP8: 0 | NQ8: 0 | NR8: 0 | NS8: 0 | NT8: 0 | NU8: 0 | NV8: 0 | NW8: 0 | NX8: 0 | NY8: 0 | NZ8: 0 | OA8: 0 | OB8: 0 | OC8: 0 | OD8: 0 | OE8: 0 | OF8: 0 | OG8: 0 | OH8: 0 | OI8: 0 | OJ8: 0 | OK8: 0 | OL8: 0 | OM8: 0 | ON8: 0 | OO8: 0 | OP8: 0 | OQ8: 0 | OR8: 0 | OS8: 0 | OT8: 0 | OU8: 0 | OV8: 0 | OW8: 0 | OX8: 0 | OY8: 0 | OZ8: 0 | PA8: 0 | PB8: 0 | PC8: 0 | PD8: 0 | PE8: 0 | PF8: 0 | PG8: 0 | PH8: 0 | PI8: 0 | PJ8: 0 | PK8: 0 | PL8: 0 | PM8: 0 | PN8: 0 | PO8: 0 | PP8: 0 | PQ8: 0 | PR8: 0 | PS8: #VALUE! | PT8: #VALUE! | PU8: #VALUE! | PV8: #VALUE! | PW8: #VALUE! | PX8: #VALUE! | PY8: #VALUE! | PZ8: #VALUE! | QA8: #VALUE! | QB8: #VALUE! | QC8: #VALUE! | QD8: #VALUE! | QE8: #VALUE! | QF8: #VALUE! | QG8: #VALUE! | QH8: #VALUE! | QI8: #VALUE! | QJ8: #VALUE! | QK8: #VALUE! | QL8: #VALUE! | QM8: #VALUE! | QN8: #VALUE! | QO8: #VALUE! | QP8: #VALUE! | QQ8: 0 | QR8: 0 | QS8: 0 | QT8: 0 | QU8: 0 | QV8: 0 | QW8: 0 | QX8: 0 | QY8: 0 | QZ8: 0 | RA8: 0 | RB8: 0 | RC8: 0 | RD8: 0 | RE8: 0 | RF8: 0 | RG8: 0 | RH8: 0 | RI8: 0 | RJ8: 0 | RK8: 0 | RL8: 0 | RM8: 0 | RN8: 0 | RO8: 0 | RP8: 0 | RQ8: 0 | RR8: 0 | RS8: 0 | RT8: 0 | RU8: 0 | RV8: 0 | RW8: 0 | RX8: 0 | RY8: 0 | RZ8: 0 | SA8: 0 | SB8: 0 | SC8: 0 | SD8: 0 | SE8: 0 | SF8: 0 | SG8: 0 | SH8: 0 | SI8: 0 | SJ8: 0 | SK8: 0 | SL8: 0 | SM8: 0 | SN8: 0 | SO8: 0 | SP8: 0 | SQ8: 0 | SR8: 0 | SS8: 0 | ST8: 0 | SU8: 0 | SV8: 0 | SW8: 0 | SX8: 0 | SY8: 0 | SZ8: 0 | TA8: 0 | TB8: 0 | TC8: 0 | TD8: 0 | TE8: 0 | TF8: 0 | TG8: 0 | TH8: 0 | TI8: 0 | TJ8: 0 | TK8: 0 | TL8: 0 | TM8: 0 | TN8: 0 | TO8: 0 | TP8: 0 | TQ8: 0 | TR8: 0 | TS8: 0 | TT8: 0 | TU8: 0 | TV8: 0 | TW8: 0 | TX8: 0 | TY8: 0 | TZ8: 0 | UA8: 0 | UB8: 0 | UC8: 0 | UD8: 0 | UE8: 0 | UF8: 0 | UG8: 0 | UH8: 0 | UI8: 0 | UJ8: 0 | UK8: 0 | UL8: 0 | UM8: 0 | UN8: 0 | UO8: 0 | UP8: 0 | UQ8: 0 | UR8: 0 | US8: 0 | UT8: 0 | UU8: 0 | UV8: 0 | UW8: 0 | UX8: 0 | UY8: 0 | UZ8: 0 | VA8: 0 | VB8: 0 | VC8: 0 | VD8: 0 | VE8: 0 | VF8: 0 | VG8: 0 | VH8: 0 | VI8: 0 | VJ8: 0 | VK8: 0 | VL8: 0 | VM8: 0 | VN8: 0 | VO8: 0 | VP8: 0 | VQ8: 0 | VR8: 0 | VS8: 0 | VT8: 0 | VU8: 0 | VV8: 0 | VW8: 0 | VX8: 0 | VY8: 0 | VZ8: 0 | WA8: 0 | WB8: 0 | WC8: 0 | WD8: 0 | WE8: 0 | WF8: 0 | WG8: 0 | WH8: 0 | WI8: 0 | WJ8: 0 | WK8: 0 | WL8: 0 | WM8: 0 | WN8: 0 | WO8: 0 | WP8: 0 | WQ8: 0 | WR8: 0 | WS8: 0 | WT8: 0 | WU8: 0 | WV8: 0 | WW8: 0 | WX8: 0 | WY8: 0 | WZ8: 0 | XA8: 0 | XB8: 0 | XC8: 0 | XD8: 0 | XE8: 0 | XF8: 0 | XG8: 0 | XH8: 0 | XI8: 0 | XJ8: 0 | XK8: 0 | XL8: 0 | XM8: 0 | XN8: 0 | XO8: 0 | XP8: 0 | XQ8: 0 | XR8: 0 | XS8: 0 | XT8: 0 | XU8: 0 | XV8: 0 | XW8: 0 | XX8: 0 | XY8: 0 | XZ8: 0 | YA8: 0 | YB8: 0 | YC8: 0 | YD8: 0 | YE8: 0 | YF8: 0 | YG8: 0 | YH8: 0 | YI8: #VALUE! | YJ8: #VALUE! | YK8: 0 | YL8: 0 | YM8: #VALUE! | YN8: #VALUE! | YO8: #VALUE! | YP8: #VALUE! | YQ8: 0 | YR8: 0 | YS8: 0 | YT8: 0 | YU8: 0 | YV8: 0 | YW8: 0 | YX8: 0 | YY8: 0 | YZ8: 0 | ZA8: 0 | ZB8: 0 | ZC8: 0 | ZD8: 0 | ZE8: #VALUE! | ZF8: #VALUE! | ZG8: 0 | ZH8: #VALUE! | ZI8: #VALUE! | ZJ8: #VALUE! | ZK8: #VALUE! | ZL8: #VALUE! | ZM8: #VALUE! | ZN8: #VALUE! | ZO8: 0 | ZP8: 0 | ZQ8: 0 | ZR8: 0 | ZS8: 0 | ZT8: 0 | ZU8: 0 | ZV8: 0 | ZW8: 0 | ZX8: 0 | ZY8: 0 | ZZ8: 0 | AAA8: 0 | AAB8: 0 | AAC8: #VALUE! | AAD8: #VALUE! | AAE8: #VALUE! | AAF8: #VALUE! | AAG8: #VALUE! | AAH8: #VALUE! | AAI8: #VALUE! | AAJ8: #VALUE! | AAK8: #VALUE! | AAL8: #VALUE! | AAM8: 0 | AAN8: 0 | AAO8: 0 | AAP8: 0 | AAQ8: 0 | AAR8: 0 | AAS8: 0 | AAT8: 0 | AAU8: #VALUE! | AAV8: #VALUE! | AAW8: #VALUE! | AAX8: #VALUE! | AAY8: #VALUE! | AAZ8: #VALUE! | ABA8: #VALUE! | ABB8: #VALUE! | ABC8: #VALUE! | ABD8: #VALUE! | ABE8: #VALUE! | ABF8: #VALUE! | ABG8: #VALUE! | ABH8: #VALUE! | ABI8: #VALUE! | ABJ8: #VALUE! | ABK8: #VALUE! | ABL8: #VALUE! | ABM8: #VALUE! | ABN8: #VALUE! | ABO8: #VALUE! | ABP8: #VALUE! | ABQ8: #VALUE! | ABR8: #VALUE! | ABS8: #VALUE! | ABT8: #VALUE! | ABU8: #VALUE! | ABV8: #VALUE! | ABW8: #VALUE! | ABX8: #VALUE! | ABY8: #VALUE! | ABZ8: #VALUE! | ACA8: #VALUE! | ACB8: #VALUE! | ACC8: #VALUE! | ACD8: #VALUE! | ACE8: #VALUE! | ACF8: #VALUE! | ACG8: #VALUE! | ACH8: #VALUE! | ACI8: #VALUE! | ACJ8: #VALUE! | ACK8: #VALUE! | ACL8: #VALUE! | ACM8: #VALUE! | ACN8: #VALUE! | ACO8: #VALUE! | ACP8: #VALUE!
A13: TOTAL MES | C13: =SUM(C8:C12) -> 11 | D13: =SUM(D8:D12) -> #VALUE! | E13: =SUM(E8:E12) -> #VALUE! | F13: =SUM(F8:F12) -> #VALUE! | G13: =SUM(G8:G12) -> #VALUE! | H13: =SUM(H8:H12) -> #VALUE! | I13: =SUM(I8:I12) -> #VALUE! | J13: =SUM(J8:J12) -> #VALUE! | ... ACP13: =SUM(ACP8:ACP12) -> #VALUE!
T26: ENERO | V26: FEBRERO | X26: MARZO | Z26: ABRIL | AB26: MAYO | AD26: JUNIO | AF26: JULIO | AH26: AGOSTO | AJ26: SEPTIEMBRE | AL26: OCTUBRE | AN26: NOVIEMBRE | AP26: DICIEMBRE
T27: ENERO | V27: FEBRERO | X27: MARZO | Z27: ABRIL
T28: MARZO
T29: ABRIL
T30: MAYO
T31: JUNIO
T32: JULIO
T33: AGOSTO
T34: SEPTIEMBRE
T35: OCTUBRE
T36: NOVIEMBRE
T37: DICIEMBRE

Sheet CRONOGRAMA
E1: PROGRAMA DE CAPACITACIÓN Y ENTRENAMIENTO ANUAL
E2: Fecha: 24/05/2023 Versión: 14 HSEQ-PRG-10 | AN2: Libro 1 de 7
A3: ITEM | B3: GRUPO | E3: TEMA | F3: SUBTEMA - TEMARIO | G3: DEDICACIÓN ESTIMADA (Horas) | H3: OBJETIVO | I3: METODOLOGIA | J3: ENE | L3: FEB | N3: MAR | P3: ABR | R3: MAY | T3: JUN | V3: JUL | X3: AGOS | Z3: SEP | AB3: OCT | AD3: NOV | AF3: DIC | AH3: COBERTURA | AM3: RECURSOS PRESUPUESTADOS | AN3: RECURSOS UTILIZADOS | AO3: RESPONSABLE
J4: P | K4: E | L4: P | M4: E | N4: P | O4: E | P4: P | Q4: E | R4: P | S4: E | T4: P | U4: E | V4: P | W4: E | X4: P | Y4: E | Z4: P | AA4: E | AB4: P | AC4: E | AD4: P | AE4: E | AF4: P | AG4: E
B5: ADMON | C5: PERSONAL PROYECTO | D5: HSEQ | J5: PROGRAMADO | K5: EJECUTADO | L5: PROGRAMADO | M5: EJECUTADO | N5: PROGRAMADO | O5: EJECUTADO | P5: PROGRAMADO | Q5: EJECUTADO | R5: PROGRAMADO | S5: EJECUTADO | T5: PROGRAMADO | U5: EJECUTADO | V5: PROGRAMADO | W5: EJECUTADO | X5: PROGRAMADO | Y5: EJECUTADO | Z5: PROGRAMADO | AA5: EJECUTADO | AB5: PROGRAMADO | AC5: EJECUTADO | AD5: PROGRAMADO | AE5: EJECUTADO | AF5: PROGRAMADO | AG5: EJECUTADO | AH5: Trim I | AI5: Trim II | AJ5: Trim III | AK5: Trim IV | AL5: Total año
A6: A | D6: X | E6: Creación Programa de Capacitación | F6: N/A | G6: N/A | H6: Establecer mecanismos para la ejecución y seguimiento adecuado del programa de capacitación de Meridian Consulting Ltda. | I6: N/A | J6: 1 | K6: 1 | AH6: =IFERROR(IF(COUNT(#REF!,J6,L6,N6)>0,COUNT(M6,K6,#REF!,O6)/COUNT(#REF!,J6,L6,N6),"Sin Actividad"), "Sin Actividad") -> 1 | AI6: =IFERROR(IF(COUNT(Q6,T6)>0,COUNT(U6,R6)/COUNT(P6,S6),"Sin Actividad"), "Sin Actividad") -> Sin Actividad | AJ6: =IFERROR(IF(COUNT(V6,X6,Z6)>0,COUNT(AA6,Y6,W6)/COUNT(V6,X6,Z6),"Sin Actividad"), "Sin Actividad") -> Sin Actividad | AK6: =IFERROR(IF(COUNT(AB6,AC6,AF6)>0,COUNT(AB6,AD6,AG6)/COUNT(AB6,AC6,AE6),"Sin Actividad"), "Sin Actividad") -> Sin Actividad | AL6: =IFERROR(AVERAGE(AH6:AK6),"Sin Actividad") -> 1 | AM6: Computador, Instalaciones de la empresa. | AN6: Computador, Instalaciones de la empresa. | AO6: Coordinador HSEQ
A7: B | D7: X | E7: Creación Contenido Virtual Meridian | AH7: =IFERROR(IF(COUNT(#REF!,J7,L7,N7)>0,COUNT(M7,K7,#REF!,O7)/COUNT(#REF!,J7,L7,N7),"Sin Actividad"), "Sin Actividad") -> Sin Actividad | AI7: =IFERROR(IF(COUNT(Q7,T7)>0,COUNT(U7,R7)/COUNT(P7,S7),"Sin Actividad"), "Sin Actividad") -> Sin Actividad | AJ7: =IFERROR(IF(COUNT(V7,X7,Z7)>0,COUNT(AA7,Y7,W7)/COUNT(V7,X7,Z7),"Sin Actividad"), "Sin Actividad") -> Sin Actividad | AK7: =IFERROR(IF(COUNT(AB7,AC7,AF7)>0,COUNT(AB7,AD7,AG7)/COUNT(AB7,AC7,AE7),"Sin Actividad"), "Sin Actividad") -> Sin Actividad | AL7: =IFERROR(AVERAGE(AH7:AK7),"Sin Actividad") -> Sin Actividad | AM7: Computador, Instalaciones de la empresa. | AN7: Computador, Instalaciones de la empresa.
A8: C | D8: X | E8: Seguimiento y Analisis del Programa | J8: 1 | K8: 1 | L8: 1 | M8: 1 | N8: 1 | O8: 1 | P8: 1 | Q8: 1 | R8: 1 | S8: 1 | T8: 1 | U8: 1 | AH8: =IFERROR(IF(COUNT(#REF!,J8,L8,N8)>0,COUNT(M8,K8,#REF!,O8)/COUNT(#REF!,J8,L8,N8),"Sin Actividad"), "Sin Actividad") -> 1 | AI8: =IFERROR(IF(COUNT(Q8,T8)>0,COUNT(U8,R8)/COUNT(P8,S8),"Sin Actividad"), "Sin Actividad") -> 1 | AJ8: =IFERROR(IF(COUNT(V8,X8,Z8)>0,COUNT(AA8,Y8,W8)/COUNT(V8,X8,Z8),"Sin Actividad"), "Sin Actividad") -> Sin Actividad | AK8: =IFERROR(IF(COUNT(AB8,AC8,AF8)>0,COUNT(AB8,AD8,AG8)/COUNT(AB8,AC8,AE8),"Sin Actividad"), "Sin Actividad") -> Sin Actividad | AL8: =IFERROR(AVERAGE(AH8:AK8),"Sin Actividad") -> 1 | AM8: Computador, Instalaciones de la empresa. | AN8: Computador, Instalaciones de la empresa.
A9: D | D9: X | E9: Revisión y Actualización de Procedimiento de Capacitación | AH9: =IFERROR(IF(COUNT(#REF!,J9,L9,N9)>0,COUNT(M9,K9,#REF!,O9)/COUNT(#REF!,J9,L9,N9),"Sin Actividad"), "Sin Actividad") -> Sin Actividad | AI9: =IFERROR(IF(COUNT(Q9,T9)>0,COUNT(U9,R9)/COUNT(P9,S9),"Sin Actividad"), "Sin Actividad") -> Sin Actividad | AJ9: =IFERROR(IF(COUNT(V9,X9,Z9)>0,COUNT(AA9,Y9,W9)/COUNT(V9,X9,Z9),"Sin Actividad"), "Sin Actividad") -> Sin Actividad | AK9: =IFERROR(IF(COUNT(AB9,AC9,AF9)>0,COUNT(AB9,AD9,AG9)/COUNT(AB9,AC9,AE9),"Sin Actividad"), "Sin Actividad") -> Sin Actividad | AL9: =IFERROR(AVERAGE(AH9:AK9),"Sin Actividad") -> Sin Actividad | AM9: Computador, Instalaciones de la empresa. | AN9: Computador, Instalaciones de la empresa.
A10: 1 | B10: X | C10: X | D10: X | E10: Inducción y/o Reinducción HSEQ | F10: Alcance sistema de Gestión Integrado Política Corporativa HSEQ Política para la prevención de consumo de Alcohol Drogas y Tabaco Política Corporativa de Seguridad Vial Política de Corporativa de Responsabilidad Social Políticas del cliente Objetivos HSEQ Reglamento de Higiene y Seguridad Industrial COPASST - Integrantes y Funciones Comité de Convivencia - Integrantes y Funciones Plan de preparación y respuesta ante emergencias (SSTA) Factores de riesgos y peligros en SST Programa(s) de Gestión de riesgos críticos y Programa(s) de Vigilancia Epidemiológica Riesgos de salud publica de la región donde labora el trabajador Ergonomía en el puesto de trabajo Aspectos e impactos ambientales inherentes al cargos y sus controles Riesgos y controles del proceso o proyecto Gestión del cambio Lecciones aprendidas Procedimiento de reporte e Investigación de Incidentes/accidentes Procedimiento control de documentos, control de registros Reporte de actos y Condiciones Inseguras Sistema de riesgos laborales ARL Procedimiento acciones Correctivas, Preventivas y de Mejora. Análisis de trabajo seguro y permiso de trabajo Uso y mantenimiento de EPP Manejo de PQRS | G10: 3 | H10: Brindar el conocimiento básico sobre el Sistema de Gestión Integral, Informar al trabajador sobre las características de su trabajo y comunicar lineamientos y políticas internas y del cliente. | I10: Virtual | J10: 12 | K10: 12 | L10: 17 | M10: 17 | N10: 5 | O10: 5 | P10: 6 | Q10: 6 | R10: 3 | S10: 3 | T10: 4 | U10: 4 | AH10: =IFERROR(IF(SUM(J10,L10,N10)>0,SUM(M10,K10,O10)/SUM(J10,L10,N10),"Sin Actividad"), "Sin Actividad") -> 1 | AI10: =IFERROR(IF(SUM(P10,R10,T10)>0,SUM(Q10,S10,U10)/SUM(P10,R10,T10),"Sin Actividad"), "Sin Actividad") -> 1 | AJ10: =IFERROR(IF(COUNT(V10,X10,Z10)>0,COUNT(AA10,Y10,W10)/COUNT(V10,X10,Z10),"Sin Actividad"), "Sin Actividad") -> Sin Actividad | AK10: =IFERROR(IF(COUNT(AB10,AC10,AF10)>0,COUNT(AB10,AD10,AG10)/COUNT(AB10,AC10,AE10),"Sin Actividad"), "Sin Actividad") -> Sin Actividad | AL10: =IFERROR(AVERAGE(AH10:AK10),"Sin Actividad") -> 1 | AM10: Computador, Instalaciones de la empresa. | AN10: Computador, Instalaciones de la empresa. | AO10: Gestión HSEQ
A11: 2 | B11: X | C11: X | D11: X | E11: Induccion al cargo | F11: Objeto del cargo o servicio prestado Funciones o actividades a ejecutar (Perfil del cargo o servicio y cronograma) Responsabilidades del Cargo Responsabilidad de Indicadores asociados Documentos asociados (Procedimientos, formatos) Rendición de cuentas, frecuencia y contenido de informes Orientación y aclaración para la realización actividades a desarrollar Autoridad Manejo de plataformas, usuarios y contraseñas Asignación de puesto de trabajo Presentación al grupo de trabajo | G11: 2 | H11: Brindar los conocimientos necesarios para que el personal nuevo este capacitado para el cargo a desempeñar | I11: Virtual | J11: 7 | K11: 7 | L11: 3 | M11: 3 | N11: 4 | O11: 4 | P11: 2 | Q11: 2 | R11: 1 | S11: 1 | AH11: =IFERROR(IF(SUM(J11,L11,N11)>0,SUM(M11,K11,O11)/SUM(J11,L11,N11),"Sin Actividad"), "Sin Actividad") -> 1 | AI11: =IFERROR(IF(SUM(P11,R11,T11)>0,SUM(Q11,S11,U11)/SUM(P11,R11,T11),"Sin Actividad"), "Sin Actividad") -> 1 | AJ11: =IFERROR(IF(COUNT(V11,X11,Z11)>0,COUNT(AA11,Y11,W11)/COUNT(V11,X11,Z11),"Sin Actividad"), "Sin Actividad") -> Sin Actividad | AK11: =IFERROR(IF(COUNT(AB11,AC11,AF11)>0,COUNT(AB11,AD11,AG11)/COUNT(AB11,AC11,AE11),"Sin Actividad"), "Sin Actividad") -> Sin Actividad | AL11: =IFERROR(AVERAGE(AH11:AK11),"Sin Actividad") -> 1 | AM11: Computador, Instalaciones de la empresa. | AN11: Computador, Instalaciones de la empresa. | AO11: Gestión HSEQ
A12: 3 | B12: X | C12: X | D12: X | E12: Inducción de Gestión Humana | F12: Reseña Histórica de la empresa Misión Visión Reglamento Interno de Trabajo (Resumen) Código de Ética Manual de Convivencia Acoso Laboral Políticas de Gestión Humana Mecanismos de comunicación Contrato y anexos Seguridad Social y prestaciones sociales Uso de carné, correo y demás elementos suministrados | G12: 2 | H12: Brindar a los todos los trabajadores y contratistas de MERIDIAN CONSULTING LTDA., una orientación efectiva en cuanto a la estructura general de la empresa, funciones o actividades del cargo o servicio a prestar y de acuerdo a las necesidades y hallazgos, realizar e implementar el programa de capacitación y entrenamiento para la correcta y segura ejecución de las actividades | I12: Virtual | J12: 12 | K12: 12 | L12: 17 | M12: 17 | N12: 5 | O12: 5 | P12: 6 | Q12: 6 | R12: 3 | S12: 3 | T12: 4 | U12: 4 | AH12: =IFERROR(IF(SUM(J12,L12,N12)>0,SUM(M12,K12,O12)/SUM(J12,L12,N12),"Sin Actividad"), "Sin Actividad") -> 1 | AI12: =IFERROR(IF(SUM(P12,R12,T12)>0,SUM(Q12,S12,U12)/SUM(P12,R12,T12),"Sin Actividad"), "Sin Actividad") -> 1 | AJ12: =IFERROR(IF(COUNT(V12,X12,Z12)>0,COUNT(AA12,Y12,W12)/COUNT(V12,X12,Z12),"Sin Actividad"), "Sin Actividad") -> Sin Actividad | AK12: =IFERROR(IF(COUNT(AB12,AC12,AF12)>0,COUNT(AB12,AD12,AG12)/COUNT(AB12,AC12,AE12),"Sin Actividad"), "Sin Actividad") -> Sin Actividad | AL12: =IFERROR(AVERAGE(AH12:AK12),"Sin Actividad") -> 1 | AM12: Computador, Instalaciones de la empresa. | AN12: Computador, Instalaciones de la empresa. | AO12: Gestión HSEQ
A13: 4 | B13: X | C13: X | D13: X | E13: Primer Respondiente "Gente que Ayuda". | F13: Desempeño básico ante situaciones de emergencia Incendios. RCP y atoramiento Quemaduras y electrocución. Golpes, heridas y fracturas. Desmayos, convulsiones, hipotermia y parto. Temblores y terremotos. | G13: 2 | H13: Brindar los conocimientos necesarios para que el personal de Meridian actué como primer respondiente ante situaciones de emergencia. | I13: Virtual | L13: 2 | M13: 2 | N13: 2 | O13: 2 | P13: 15 | Q13: 15 | R13: 1 | S13: 1 | AH13: =IFERROR(IF(SUM(J13,L13,N13)>0,SUM(M13,K13,O13)/SUM(J13,L13,N13),"Sin Actividad"), "Sin Actividad") -> 1 | AI13: =IFERROR(IF(SUM(P13,R13,T13)>0,SUM(Q13,S13,U13)/SUM(P13,R13,T13),"Sin Actividad"), "Sin Actividad") -> 1 | AJ13: =IFERROR(IF(COUNT(V13,X13,Z13)>0,COUNT(AA13,Y13,W13)/COUNT(V13,X13,Z13),"Sin Actividad"), "Sin Actividad") -> Sin Actividad | AK13: =IFERROR(IF(COUNT(AB13,AC13,AF13)>0,COUNT(AB13,AD13,AG13)/COUNT(AB13,AC13,AE13),"Sin Actividad"), "Sin Actividad") -> Sin Actividad | AL13: =IFERROR(AVERAGE(AH13:AK13),"Sin Actividad") -> 1 | AM13: Computador, Instalaciones de la empresa. | AN13: Computador, Instalaciones de la empresa. | AO13: Gestión HSEQ
A14: 5 | B14: X | C14: X | D14: X | E14: Seguridad Víal | F14: 1. Valores Universales 2. Conciencia Víal 3. Actores Víales 4. Velocidad | G14: 2 | H14: Inducción Seguridad Víal | I14: Víal | L14: 36 | M14: 36 | AH14: =IFERROR(IF(SUM(J14,L14,N14)>0,SUM(M14,K14,O14)/SUM(J14,L14,N14),"Sin Actividad"), "Sin Actividad") -> 1 | AI14: =IFERROR(IF(SUM(P14,R14,T14)>0,SUM(Q14,S14,U14)/SUM(P14,R14,T14),"Sin Actividad"), "Sin Actividad") -> Sin Actividad | AJ14: =IFERROR(IF(COUNT(V14,X14,Z14)>0,COUNT(AA14,Y14,W14)/COUNT(V14,X14,Z14),"Sin Actividad"), "Sin Actividad") -> Sin Actividad | AK14: =IFERROR(IF(COUNT(AB14,AC14,AF14)>0,COUNT(AB14,AD14,AG14)/COUNT(AB14,AC14,AE14),"Sin Actividad"), "Sin Actividad") -> Sin Actividad | AL14: =IFERROR(AVERAGE(AH14:AK14),"Sin Actividad") -> 1 | AM14: Computador, Instalaciones de la empresa. | AN14: Computador, Instalaciones de la empresa. | AO14: Gestión HSEQ
A15: 6 | B15: X | C15: X | E15: Riesgo Publico & Derechos Humanos | F15: 1. Sección 1: Riesgo Público: Identificación, Prevención y Autocuidado 2. Sección 2: Promoción de los Derechos Humanos 3. Sección 3: Derechos Humanos en el Ámbito Laboral - Política de Riesgo Público Y DDHH | G15: 8 | H15: Fortalecer las competencias de los trabajadores para identificar, prevenir y actuar de manera segura frente a situaciones de riesgo público, promoviendo comportamientos seguros que protejan la vida, los bienes y la continuidad de las operaciones de la organización. | I15: Virtual | N15: 37 | O15: 37 | AH15: =IFERROR(IF(SUM(J15,L15,N15)>0,SUM(M15,K15,O15)/SUM(J15,L15,N15),"Sin Actividad"), "Sin Actividad") -> 1 | AI15: =IFERROR(IF(SUM(P15,R15,T15)>0,SUM(Q15,S15,U15)/SUM(P15,R15,T15),"Sin Actividad"), "Sin Actividad") -> Sin Actividad | AJ15: =IFERROR(IF(COUNT(V15,X15,Z15)>0,COUNT(AA15,Y15,W15)/COUNT(V15,X15,Z15),"Sin Actividad"), "Sin Actividad") -> Sin Actividad | AK15: =IFERROR(IF(COUNT(AB15,AC15,AF15)>0,COUNT(AB15,AD15,AG15)/COUNT(AB15,AC15,AE15),"Sin Actividad"), "Sin Actividad") -> Sin Actividad | AL15: =IFERROR(AVERAGE(AH15:AK15),"Sin Actividad") -> 1 | AM15: Computador, Instalaciones de la empresa. | AN15: Computador, Instalaciones de la empresa. | AO15: Gestión HSEQ
A16: 7 | B16: X | C16: X | E16: SAGRILAFT | F16: Lavado de Activos (LA) Financiación del Terrorismo (FT) Financiamiento de la Proliferación de Armas de Destrucción Masiva (FPADM) Diferencias entre LA/FT Sujetos obligados | G16: 2 | H16: Con el fin de fortalecer el conocimiento y cumplimiento de las disposiciones relacionadas con el Sistema de Autocontrol y Gestión del Riesgo Integral de Lavado de Activos, Financiación del Terrorismo y Proliferación de Armas de Destrucción Masiva | I16: Virtual | T16: 21 | U16: 21 | V16: 11 | AH16: =IFERROR(IF(SUM(J16,L16,N16)>0,SUM(M16,K16,O16)/SUM(J16,L16,N16),"Sin Actividad"), "Sin Actividad") -> Sin Actividad | AI16: =IFERROR(IF(SUM(P16,R16,T16)>0,SUM(Q16,S16,U16)/SUM(P16,R16,T16),"Sin Actividad"), "Sin Actividad") -> 1 | AJ16: =IFERROR(IF(COUNT(V16,X16,Z16)>0,COUNT(AA16,Y16,W16)/COUNT(V16,X16,Z16),"Sin Actividad"), "Sin Actividad") -> 0 | AK16: =IFERROR(IF(COUNT(AB16,AC16,AF16)>0,COUNT(AB16,AD16,AG16)/COUNT(AB16,AC16,AE16),"Sin Actividad"), "Sin Actividad") -> Sin Actividad | AL16: =IFERROR(AVERAGE(AH16:AK16),"Sin Actividad") -> 0.5 | AM16: Computador, Instalaciones de la empresa. | AN16: Computador, Instalaciones de la empresa. | AO16: Gestión HSEQ
A17: 8 | B17: X | C17: X | E17: Excelencia_HSE | F17: 1 ¿Qué es HSE y por qué es importante? Significado y beneficios para las personas, la empresa y el entorno. 2 Cultura de seguridad y autocuidado Comportamientos seguros, reportes de actos y condiciones inseguras. Responsabilidad individual y colectiva. 3 Pilares de la salud ocupacional Prevención de enfermedades laborales. Promoción de hábitos saludables. Exámenes médicos ocupacionales. 4 Gestión de la seguridad Identificación de peligros y evaluación de riesgos. Controles operacionales, uso correcto de EPP, permisos de trabajo. 5 Protección del medio ambiente Manejo adecuado de residuos, consumo responsable de recursos. Prevención de la contaminación. 6 Cumplimiento legal y normativo Leyes y normas HSE aplicables. Rol del trabajador en el cumplimiento. 7 Mejora continua en HSE Indicadores, auditorías internas, participación de los trabajadores. Lecciones aprendidas e innovación en seguridad y sostenibilidad. Espacios Confinados | G17: 8 | H17: Fomentar en los participantes una cultura de prevención, autocuidado y compromiso con la salud, la seguridad y la protección del medio ambiente, a través del fortalecimiento de conocimientos, actitudes y prácticas que contribuyan al cumplimiento de los estándares HSE y a la mejora continua en los entornos laborales. | I17: Virtual | AH17: =IFERROR(IF(SUM(J17,L17,N17)>0,SUM(M17,K17,O17)/SUM(J17,L17,N17),"Sin Actividad"), "Sin Actividad") -> Sin Actividad | AI17: =IFERROR(IF(SUM(P17,R17,T17)>0,SUM(Q17,S17,U17)/SUM(P17,R17,T17),"Sin Actividad"), "Sin Actividad") -> Sin Actividad | AJ17: =IFERROR(IF(COUNT(V17,X17,Z17)>0,COUNT(AA17,Y17,W17)/COUNT(V17,X17,Z17),"Sin Actividad"), "Sin Actividad") -> Sin Actividad | AK17: =IFERROR(IF(COUNT(AB17,AC17,AF17)>0,COUNT(AB17,AD17,AG17)/COUNT(AB17,AC17,AE17),"Sin Actividad"), "Sin Actividad") -> Sin Actividad | AL17: =IFERROR(AVERAGE(AH17:AK17),"Sin Actividad") -> Sin Actividad | AM17: Computador, Instalaciones de la empresa. | AN17: Computador, Instalaciones de la empresa. | AO17: Gestión HSEQ
A18: 9 | B18: X | C18: X | E18: Salud Publica | F18: 1 ¿Qué es salud pública? Cuidado de la salud de toda la comunidad. 2 Prevención de enfermedades Higiene, vacunación, alimentación saludable. 3 Promoción de estilos de vida saludables Ejercicio, no fumar, cuidar la salud mental. 4 Salud ambiental Manejo de residuos, agua limpia, aire puro. 5 Acceso a servicios de salud Rutas de atención y derechos en salud. 6 Respuesta a emergencias sanitarias Qué hacer en caso de brotes o desastres. | G18: 8 | H18: Brindar a los participantes conocimientos básicos sobre salud pública, sus principales áreas de acción y su impacto en la comunidad, con el fin de fomentar hábitos saludables, prevenir enfermedades y promover el bienestar colectivo a través de la participación activa y el autocuidado. | I18: Virtual | AH18: =IFERROR(IF(SUM(J18,L18,N18)>0,SUM(M18,K18,O18)/SUM(J18,L18,N18),"Sin Actividad"), "Sin Actividad") -> Sin Actividad | AI18: =IFERROR(IF(SUM(P18,R18,T18)>0,SUM(Q18,S18,U18)/SUM(P18,R18,T18),"Sin Actividad"), "Sin Actividad") -> Sin Actividad | AJ18: =IFERROR(IF(COUNT(V18,X18,Z18)>0,COUNT(AA18,Y18,W18)/COUNT(V18,X18,Z18),"Sin Actividad"), "Sin Actividad") -> Sin Actividad | AK18: =IFERROR(IF(COUNT(AB18,AC18,AF18)>0,COUNT(AB18,AD18,AG18)/COUNT(AB18,AC18,AE18),"Sin Actividad"), "Sin Actividad") -> Sin Actividad | AL18: =IFERROR(AVERAGE(AH18:AK18),"Sin Actividad") -> Sin Actividad | AM18: Computador, Instalaciones de la empresa. | AN18: Computador, Instalaciones de la empresa. | AO18: Gestión HSEQ
A19: 10 | B19: X | C19: X | E19: Conservación y Cuidado del Medio Ambiente | F19: 1 ¿Qué es el medio ambiente y por qué debemos cuidarlo? Importancia del aire, agua, suelo, flora y fauna. 2 Problemas ambientales actuales Contaminación, cambio climático, deforestación, pérdida de biodiversidad. 3 Separación y manejo adecuado de residuos Basura orgánica, reciclaje, residuos peligrosos. 4 Uso responsable de los recursos naturales Ahorro de agua, energía y materiales. 5 Buenas prácticas ambientales en el hogar y el trabajo Reducir, reutilizar y reciclar (Regla de las 3R). Evitar plásticos de un solo uso. 6 Participación y compromiso individual y colectivo Cómo cada persona puede aportar a un planeta más limpio. | G19: 8 | H19: Sensibilizar y capacitar a los participantes sobre la importancia de proteger el medio ambiente, promoviendo prácticas responsables como el uso eficiente de los recursos, la correcta gestión de residuos y la reducción de impactos negativos, con el fin de contribuir a la sostenibilidad del entorno en el hogar, el trabajo y la comunidad. | I19: Virtual | AH19: =IFERROR(IF(SUM(J19,L19,N19)>0,SUM(M19,K19,O19)/SUM(J19,L19,N19),"Sin Actividad"), "Sin Actividad") -> Sin Actividad | AI19: =IFERROR(IF(SUM(P19,R19,T19)>0,SUM(Q19,S19,U19)/SUM(P19,R19,T19),"Sin Actividad"), "Sin Actividad") -> Sin Actividad | AJ19: =IFERROR(IF(COUNT(V19,X19,Z19)>0,COUNT(AA19,Y19,W19)/COUNT(V19,X19,Z19),"Sin Actividad"), "Sin Actividad") -> Sin Actividad | AK19: =IFERROR(IF(COUNT(AB19,AC19,AF19)>0,COUNT(AB19,AD19,AG19)/COUNT(AB19,AC19,AE19),"Sin Actividad"), "Sin Actividad") -> Sin Actividad | AL19: =IFERROR(AVERAGE(AH19:AK19),"Sin Actividad") -> Sin Actividad | AM19: Computador, Instalaciones de la empresa. | AN19: Computador, Instalaciones de la empresa. | AO19: Gestión HSEQ
A20: 11 | C20: X | E20: Well control | F20: Según el marco del programa WellSharp de la IADC,: Causas de surgencias,Complicaciones,Regulaciones,Procedimientos de cierre, Detección de surgencias,Fluidos, Señales de advertencia de surgencias,Procedimientos de ahogo, Teoría de surgencia, Equipamiento de BOP,Sacada y Bajada de Tubería/ Inserción de Tubería bajo,presión Métodos de presión constante de fondo de pozo.) | G20: 32 | H20: Enseñar principios básicos y teoría de control de pozos, así como las técnicas de control de pozos más utilizadas. | I20: Virtual / Presencial | J20: 1 | K20: 1 | L20: 4 | M20: 4 | R20: 1 | S20: 1 | AH20: =IFERROR(IF(SUM(J20,L20,N20)>0,SUM(M20,K20,O20)/SUM(J20,L20,N20),"Sin Actividad"), "Sin Actividad") -> 1 | AI20: =IFERROR(IF(SUM(P20,R20,T20)>0,SUM(Q20,S20,U20)/SUM(P20,R20,T20),"Sin Actividad"), "Sin Actividad") -> 1 | AJ20: =IFERROR(IF(COUNT(V20,X20,Z20)>0,COUNT(AA20,Y20,W20)/COUNT(V20,X20,Z20),"Sin Actividad"), "Sin Actividad") -> Sin Actividad | AK20: =IFERROR(IF(COUNT(AB20,AC20,AF20)>0,COUNT(AB20,AD20,AG20)/COUNT(AB20,AC20,AE20),"Sin Actividad"), "Sin Actividad") -> Sin Actividad | AL20: =IFERROR(AVERAGE(AH20:AK20),"Sin Actividad") -> 1 | AM20: Computador, Instalaciones de la empresa. | AN20: Computador, Instalaciones de la empresa. | AO20: Gestión HSEQ
A21: 12 | C21: X | E21: Stuck Pipe/ Pega de Tuberías | F21: Impacto de tubería pegada, Causas humanas y físicas ,Pega diferencial, Tubería pegada mecánicamente, Tubería pegada por problemas relacionados con la formación, Signos de advertencia, Prevención de pega diferencial, y por mecanismo mecánico, Calculadora de tubería pegada. | G21: 8 | H21: Capacitar en el reconocimiento de los factores que causan la pega de tuberías , así como su prevención y soluciones posibles. | I21: Virtual / Presencia | L21: 4 | M21: 4 | N21: 1 | O21: 1 | R21: 1 | S21: 1 | AH21: =IFERROR(IF(SUM(J21,L21,N21)>0,SUM(M21,K21,O21)/SUM(J21,L21,N21),"Sin Actividad"), "Sin Actividad") -> 1 | AI21: =IFERROR(IF(SUM(P21,R21,T21)>0,SUM(Q21,S21,U21)/SUM(P21,R21,T21),"Sin Actividad"), "Sin Actividad") -> 1 | AJ21: =IFERROR(IF(COUNT(V21,X21,Z21)>0,COUNT(AA21,Y21,W21)/COUNT(V21,X21,Z21),"Sin Actividad"), "Sin Actividad") -> Sin Actividad | AK21: =IFERROR(IF(COUNT(AB21,AC21,AF21)>0,COUNT(AB21,AD21,AG21)/COUNT(AB21,AC21,AE21),"Sin Actividad"), "Sin Actividad") -> Sin Actividad | AL21: =IFERROR(AVERAGE(AH21:AK21),"Sin Actividad") -> 1 | AM21: Computador, Instalaciones de la empresa. | AN21: Computador, Instalaciones de la empresa. | AO21: Gestión HSEQ
A22: 13 | C22: X | E22: Rig Pass | F22: Módulo 1 - Orientación del nuevo trabajador en un equipo de perforación Módulo 2 - Comunicación de riesgos Módulo 3 - Manejo defensivo Módulo 4 - Equipos de protección personal(EPPS) Módulo 5 - Levante manual de cargas Módulo 6 - Comunicación de riesgos y manejo de materiales peligrosos Módulo 7 - Salud ocupacional Módulo 8 - Sulfuro de hidrógeno Módulo 9 - Procedimientos especializados de trabajo Módulo 10 - Espacios confinados y permisos de trabajo Módulo 11 - Seguridad contra incendios Módulo 12 - Manejo de materiales Módulo 13 - Salud y primeros auxilios Módulo 14 - Respuesta a emergencias Módulo 15 - Protección ambiental en un taladro de perforación | G22: 8 | H22: Capacitar y entrenar a todos los trabajadores para ingresar a los equipos de operación en torre tanto en el mar como en tierra. Los conceptos del curso tratan sobre seguridad, comunicación de peligros, salud ocupacional, procedimientos especializados de trabajos, manejo de materiales, primeros auxilios, protocolos de trabajo, manejo de las relaciones, entornos en la torre o plataforma de perforación, respuesta a emergencias, transporte y seguridad en el agua. | I22: Presencial/Virtual | J22: 1 | K22: 1 | L22: 3 | M22: 3 | N22: 3 | O22: 3 | R22: 1 | S22: 1 | T22: 1 | U22: 1 | V22: 1 | W22: 1 | AH22: =IFERROR(IF(SUM(J22,L22,N22)>0,SUM(M22,K22,O22)/SUM(J22,L22,N22),"Sin Actividad"), "Sin Actividad") -> 1 | AI22: =IFERROR(IF(SUM(P22,R22,T22)>0,SUM(Q22,S22,U22)/SUM(P22,R22,T22),"Sin Actividad"), "Sin Actividad") -> 1 | AJ22: =IFERROR(IF(COUNT(V22,X22,Z22)>0,COUNT(AA22,Y22,W22)/COUNT(V22,X22,Z22),"Sin Actividad"), "Sin Actividad") -> 1 | AK22: =IFERROR(IF(COUNT(AB22,AC22,AF22)>0,COUNT(AB22,AD22,AG22)/COUNT(AB22,AC22,AE22),"Sin Actividad"), "Sin Actividad") -> Sin Actividad | AL22: =IFERROR(AVERAGE(AH22:AK22),"Sin Actividad") -> 1 | AM22: Computador, Instalaciones de la empresa. | AN22: Computador, Instalaciones de la empresa. | AO22: Gestión HSEQ
A23: 14 | C23: X | E23: Trabajo seguro en alturas: Jefes de área para trabajos en alturas. | F23: Naturaleza de los peligros de caída de personas y objetos en el área de trabajo y fomento del autocuidado de las personas. Requisitos legales en protección contra caídas para trabajo seguro en alturas, de acuerdo a la actividad económica. Responsabilidad laboral, civil, penal y administrativa. Conceptos técnicos de protección contra caídas para trabajo seguro en alturas. Medidas de prevención y protección contra caídas en trabajo desarrollado en alturas. Procedimientos para seleccionar, manipular y almacenar equipos y materiales utilizados para protección contra caídas. Conceptos básicos de autor rescate, rescate y fundamentos de primeros auxilios. Permiso de trabajo en alturas. | G23: 8 | H23: Capacitar a los trabajadores para controlar los riesgos d de trabajo en altura | I23: Virtual / Presencia | L23: 9 | M23: 9 | P23: 6 | Q23: 6 | R23: 4 | S23: 4 | T23: 2 | U23: 2 | AH23: =IFERROR(IF(SUM(J23,L23,N23)>0,SUM(M23,K23,O23)/SUM(J23,L23,N23),"Sin Actividad"), "Sin Actividad") -> 1 | AI23: =IFERROR(IF(SUM(P23,R23,T23)>0,SUM(Q23,S23,U23)/SUM(P23,R23,T23),"Sin Actividad"), "Sin Actividad") -> 1 | AJ23: =IFERROR(IF(COUNT(V23,X23,Z23)>0,COUNT(AA23,Y23,W23)/COUNT(V23,X23,Z23),"Sin Actividad"), "Sin Actividad") -> Sin Actividad | AK23: =IFERROR(IF(COUNT(AB23,AC23,AF23)>0,COUNT(AB23,AD23,AG23)/COUNT(AB23,AC23,AE23),"Sin Actividad"), "Sin Actividad") -> Sin Actividad | AL23: =IFERROR(AVERAGE(AH23:AK23),"Sin Actividad") -> 1 | AM23: Computador, Instalaciones de la empresa. | AN23: Computador, Instalaciones de la empresa. | AO23: Gestión HSEQ
A24: 15 | B24: X | C24: X | D24: X | E24: HSEQ FRONTERA | F24: 1. Salud Ocupacional 2. Emergencias 3. Gestión Ambiental 4. Seguridad Industrial 5. Calidad | G24: 4 | H24: Dar a conocer los lineamientos HSE del cliente Frontera Energy a todos los trabajadores del proyecto. | I24: Virtual | J24: 18 | K24: 18 | L24: 11 | M24: 11 | N24: 6 | O24: 6 | P24: 7 | Q24: 7 | R24: 1 | S24: 1 | T24: 1 | U24: 1 | AH24: =IFERROR(IF(SUM(J24,L24,N24)>0,SUM(M24,K24,O24)/SUM(J24,L24,N24),"Sin Actividad"), "Sin Actividad") -> 1 | AI24: =IFERROR(IF(SUM(P24,R24,T24)>0,SUM(Q24,S24,U24)/SUM(P24,R24,T24),"Sin Actividad"), "Sin Actividad") -> 1 | AJ24: =IFERROR(IF(COUNT(V24,X24,Z24)>0,COUNT(AA24,Y24,W24)/COUNT(V24,X24,Z24),"Sin Actividad"), "Sin Actividad") -> Sin Actividad | AK24: =IFERROR(IF(COUNT(AB24,AC24,AF24)>0,COUNT(AB24,AD24,AG24)/COUNT(AB24,AC24,AE24),"Sin Actividad"), "Sin Actividad") -> Sin Actividad | AL24: =IFERROR(AVERAGE(AH24:AK24),"Sin Actividad") -> 1 | AM24: Computador, Instalaciones de la empresa. | AN24: Computador, Instalaciones de la empresa. | AO24: Gestión HSEQ
A25: 16 | C25: X | E25: Control del Trabajo Frontera | F25: 1. Políticas Corporativas Frontera Energy 2. E-HSEQ-S-003 Estándar De Control Del Trabajo 3. E-HSEQ-S-004 Estándar De Seguridad Para Realizar Trabajos En Altura 4. E-HSEQ-S-005 Estándar De Seguridad Para El Levantamiento Mecánico De Cargas 5. E-HSEQ-S-006 Estándar De Seguridad Para Realizar Excavaciones 6. E-HSEQ-S-007 Estándar De Seguridad Para Trabajos En Espacios Confinados 7. E-HSEQ-S-008 Estándar De Seguridad Para Trabajos Con Energía Eléctrica 8. E-HSEQ-S-008 Estándar De Seguridad Para Realizar Aislamientos 9. E-HSEQ-S-009 Estándar Para El Levantamiento Manual De Cargas 10. E-HSEQ-S-010 Estándar De Seguridad Para Identificación De Peligros, Evaluación Y Valoración De Riesgos 11. E-HSEQ-S-011 Estándar De Seguridad Para Manejo De Productos Químicos 12. E-HSEQ-S-023 Estándar De Seguridad Vial 13. P-HSEQ-Q-014 Procedimiento Roles Y Responsabilidades De Control Del Trabajo 14. Seguridad Vial 15. Aislamientos De Energía 16. Trabajos En Altura 17. “Protegemos La Vida Controlando El Trabajo” 18. Elementos De Protección Personal 19. Espacios Confinados 20. Excavaciones 21. Identificación De Peligros, Evaluación Y Valoración De Riesgos 22. Levantamiento Manual De Carga 23. Levantamiento Mecánico De Cargas 24. Manejo De Químicos 25. “Permisos De Trabajo” | G25: 32 | H25: Reducir el riesgo al que están expuestos los tra bajadores, el medio ambiente, la operación y los equipos, protegiendo la vida y el bienesta r, a la vez que se ref uer za la discipli na operaciona l y la cultu ra segura de alto rendi miento. | I25: Virtual | J25: 13 | K25: 13 | L25: 10 | M25: 10 | N25: 3 | O25: 3 | P25: 3 | Q25: 3 | R25: 2 | S25: 2 | T25: 1 | U25: 1 | AH25: =IFERROR(IF(SUM(J25,L25,N25)>0,SUM(M25,K25,O25)/SUM(J25,L25,N25),"Sin Actividad"), "Sin Actividad") -> 1 | AI25: =IFERROR(IF(SUM(P25,R25,T25)>0,SUM(Q25,S25,U25)/SUM(P25,R25,T25),"Sin Actividad"), "Sin Actividad") -> 1 | AJ25: =IFERROR(IF(COUNT(V25,X25,Z25)>0,COUNT(AA25,Y25,W25)/COUNT(V25,X25,Z25),"Sin Actividad"), "Sin Actividad") -> Sin Actividad | AK25: =IFERROR(IF(COUNT(AB25,AC25,AF25)>0,COUNT(AB25,AD25,AG25)/COUNT(AB25,AC25,AE25),"Sin Actividad"), "Sin Actividad") -> Sin Actividad | AL25: =IFERROR(AVERAGE(AH25:AK25),"Sin Actividad") -> 1 | AM25: Computador, Instalaciones de la empresa. | AN25: Computador, Instalaciones de la empresa. | AO25: Gestión HSEQ
D28: PARÁMETRO A MEDIR
D29: CUMPLIMIENTO PROGRAMA CAPACITACIÓN ENTRENAMIENTO | J29: ENE | L29: FEB | N29: MAR | P29: ABR | R29: MAY | T29: JUN | V29: JUL | X29: AGOS | Z29: SEP | AB29: OCT | AD29: NOV | AF29: DEC
D30: Programado mensual | J30: =SUMIF(J10:J25,">0") -> 64 | L30: =SUMIF(L10:L25,">0") -> 116 | N30: =SUMIF(N10:N25,">0") -> 66 | P30: =SUMIF(P10:P25,">0") -> 45 | R30: =SUMIF(R10:R25,">0") -> 18 | T30: =SUMIF(T10:T25,">0") -> 34 | V30: =SUMIF(V10:V25,">0") -> 12 | X30: =SUMIF(X10:X25,">0") -> 0 | Z30: =SUMIF(Z10:Z25,">0") -> 0 | AB30: =SUMIF(AB10:AB25,">0") -> 0 | AD30: =SUMIF(AD10:AD25,">0") -> 0 | AF30: =SUMIF(AF10:AF25,">0") -> 0 | AH30: =IFERROR(AVERAGE(J33:AG33),"Sin Actividad Programada") -> 0.69444444
D31: Ejecutado mensual | J31: =SUMIF(K10:K25,">0") -> 64 | L31: =SUMIF(M10:M25,">0") -> 116 | N31: =SUMIF(O10:O25,">0") -> 66 | P31: =SUMIF(Q10:Q25,">0") -> 45 | R31: =SUMIF(S10:S25,">0") -> 18 | T31: =SUMIF(U10:U25,">0") -> 34 | V31: =SUMIF(W10:W25,">0") -> 1 | X31: =SUMIF(Y10:Y25,">0") -> 0 | Z31: =SUMIF(AA10:AA25,">0") -> 0 | AB31: =SUMIF(AC10:AC25,">0") -> 0 | AD31: =SUMIF(AE10:AE25,">0") -> 0 | AF31: =SUMIF(AG10:AG25,">0") -> 0
D32: % Cumplimiento mensual | J32: =IF(J30>0,J31/J30,IF(J30=0,"N,A")) -> 1 | L32: =IF(L30>0,L31/L30,IF(L30=0,"N,A")) -> 1 | N32: =IF(N30>0,N31/N30,IF(N30=0,"N,A")) -> 1 | P32: =IF(P30>0,P31/P30,IF(P30=0,"N,A")) -> 1 | R32: =IF(R30>0,R31/R30,IF(R30=0,"N,A")) -> 1 | T32: =IF(T30>0,T31/T30,IF(T30=0,"N,A")) -> 1 | V32: =IF(V30>0,V31/V30,IF(V30=0,"N,A")) -> 0.083333333 | X32: =IF(X30>0,X31/X30,IF(X30=0,"N,A")) -> N,A | Z32: =IF(Z30>0,Z31/Z30,IF(Z30=0,"N,A")) -> N,A | AB32: =IF(AB30>0,AB31/AB30,IF(AB30=0,"N,A")) -> N,A | AD32: =IF(AD30>0,AD31/AD30,IF(AD30=0,"N,A")) -> N,A | AF32: =IF(AF30>0,AF31/AF30,IF(AF30=0,"N,A")) -> N,A
D33: % Cumplimiento trimestral | J33: =IFERROR(IF(SUM(J32:O32)>=0,AVERAGE(J32:O32),"N.A."),"N,A") -> 1 | P33: =IFERROR(IF(SUM(P32:U32)>=0,AVERAGE(P32:U32),"N.A."),"N,A") -> 1 | V33: =IFERROR(IF(SUM(V32:AA32)>=0,AVERAGE(V32:AA32),"N.A."),"N,A") -> 0.083333333 | AB33: =IFERROR(IF(SUM(AB32:AG32)>=0,AVERAGE(AB32:AG32),"N.A."),"N,A") -> N,A
D34: CUMPLIMIENTO PROGRAMA INDUCCIÓN Y REINDUCCIÓN | J34: ENE | L34: FEB | N34: MAR | P34: ABR | R34: MAY | T34: JUN | V34: JUL | X34: AGOS | Z34: SEP | AB34: OCT | AD34: NOV | AF34: DEC
D35: Programado mensual | J35: =SUMIF(J10,">0")+SUMIF(J12,">0") -> 24 | L35: =SUMIF(L10,">0")+SUMIF(L12,">0") -> 34 | N35: =SUMIF(N10,">0")+SUMIF(N12,">0") -> 10 | P35: =SUMIF(P10,">0")+SUMIF(P12,">0") -> 12 | R35: =SUMIF(R10,">0")+SUMIF(R12,">0") -> 6 | T35: =SUMIF(T10,">0")+SUMIF(T12,">0") -> 8 | V35: =SUMIF(V10,">0")+SUMIF(V12,">0") -> 0 | X35: =SUMIF(X10,">0")+SUMIF(X12,">0") -> 0 | Z35: =SUMIF(Z10,">0")+SUMIF(Z12,">0") -> 0 | AB35: =SUMIF(AB10,">0")+SUMIF(AB12,">0") -> 0 | AD35: =SUMIF(AD10,">0")+SUMIF(AD12,">0") -> 0 | AF35: =SUMIF(AF10,">0")+SUMIF(AF12,">0") -> 0 | AH35: =IFERROR(AVERAGE(J38:AG38),"Sin Actividad Programada") -> 1
D36: Ejecutado mensual | J36: =SUMIF(K10,">0")+SUMIF(K12,">0") -> 24 | L36: =SUMIF(M10,">0")+SUMIF(M12,">0") -> 34 | N36: =SUMIF(O10,">0")+SUMIF(O12,">0") -> 10 | P36: =SUMIF(Q10,">0")+SUMIF(Q12,">0") -> 12 | R36: =SUMIF(S10,">0")+SUMIF(S12,">0") -> 6 | T36: =SUMIF(U10,">0")+SUMIF(U12,">0") -> 8 | V36: =SUMIF(W10,">0")+SUMIF(W12,">0") -> 0 | X36: =SUMIF(Y10,">0")+SUMIF(Y12,">0") -> 0 | Z36: =SUMIF(AA10,">0")+SUMIF(AA12,">0") -> 0 | AB36: =SUMIF(AC10,">0")+SUMIF(AC12,">0") -> 0 | AD36: =SUMIF(AE10,">0")+SUMIF(AE12,">0") -> 0 | AF36: =SUMIF(AG10,">0")+SUMIF(AG12,">0") -> 0
D37: % Cumplimiento mensual | J37: =IF(J35>0,J36/J35,IF(J35=0,"N,A")) -> 1 | L37: =IF(L35>0,L36/L35,IF(L35=0,"N,A")) -> 1 | N37: =IF(N35>0,N36/N35,IF(N35=0,"N,A")) -> 1 | P37: =IF(P35>0,P36/P35,IF(P35=0,"N,A")) -> 1 | R37: =IF(R35>0,R36/R35,IF(R35=0,"N,A")) -> 1 | T37: =IF(T35>0,T36/T35,IF(T35=0,"N,A")) -> 1 | V37: =IF(V35>0,V36/V35,IF(V35=0,"N,A")) -> N,A | X37: =IF(X35>0,X36/X35,IF(X35=0,"N,A")) -> N,A | Z37: =IF(Z35>0,Z36/Z35,IF(Z35=0,"N,A")) -> N,A | AB37: =IF(AB35>0,AB36/AB35,IF(AB35=0,"N,A")) -> N,A | AD37: =IF(AD35>0,AD36/AD35,IF(AD35=0,"N,A")) -> N,A | AF37: =IF(AF35>0,AF36/AF35,IF(AF35=0,"N,A")) -> N,A
D38: % Cumplimiento trimestral | J38: =IFERROR(IF(SUM(J37:O37)>=0,AVERAGE(J37:O37),"N.A."),"N,A") -> 1 | P38: =IFERROR(IF(SUM(P37:U37)>=0,AVERAGE(P37:U37),"N.A."),"N,A") -> 1 | V38: =IFERROR(IF(SUM(V37:AA37)>=0,AVERAGE(V37:AA37),"N.A."),"N,A") -> N,A | AB38: =IFERROR(IF(SUM(AB37:AG37)>=0,AVERAGE(AB37:AG37),"N.A."),"N,A") -> N,A
D39: CUMPLIMIENTO TAREAS CRITICAS (CAPACITACIONES OBLIGATORIAS) | J39: ENE | L39: FEB | N39: MAR | P39: ABR | R39: MAY | T39: JUN | V39: JUL | X39: AGOS | Z39: SEP | AB39: OCT | AD39: NOV | AF39: DEC
D40: Programado mensual | J40: =SUMIF(J20:J25,">0")+SUMIF(J15,">0") -> 33 | L40: =SUMIF(L20:L25,">0")+SUMIF(L15,">0") -> 41 | N40: =SUMIF(N20:N25,">0")+SUMIF(N15,">0") -> 50 | P40: =SUMIF(P20:P25,">0")+SUMIF(P15,">0") -> 16 | R40: =SUMIF(R20:R25,">0")+SUMIF(R15,">0") -> 10 | T40: =SUMIF(T20:T25,">0")+SUMIF(T15,">0") -> 5 | V40: =SUMIF(V20:V25,">0")+SUMIF(V15,">0") -> 1 | X40: =SUMIF(X20:X25,">0")+SUMIF(X15,">0") -> 0 | Z40: =SUMIF(Z20:Z25,">0")+SUMIF(Z15,">0") -> 0 | AB40: =SUMIF(AB20:AB25,">0")+SUMIF(AB15,">0") -> 0 | AD40: =SUMIF(AD20:AD25,">0")+SUMIF(AD15,">0") -> 0 | AF40: =SUMIF(AF20:AF25,">0")+SUMIF(AF15,">0") -> 0 | AH40: =IFERROR(AVERAGE(J43:AG43),"Sin Actividad Programada") -> 1
D41: Ejecutado mensual | J41: =SUMIF(K20:K25,">0")+SUMIF(K15,">0") -> 33 | L41: =SUMIF(M20:M25,">0")+SUMIF(M15,">0") -> 41 | N41: =SUMIF(O20:O25,">0")+SUMIF(O15,">0") -> 50 | P41: =SUMIF(Q20:Q25,">0")+SUMIF(Q15,">0") -> 16 | R41: =SUMIF(S20:S25,">0")+SUMIF(S15,">0") -> 10 | T41: =SUMIF(U20:U25,">0")+SUMIF(U15,">0") -> 5 | V41: =SUMIF(W20:W25,">0")+SUMIF(W15,">0") -> 1 | X41: =SUMIF(Y20:Y25,">0")+SUMIF(Y15,">0") -> 0 | Z41: =SUMIF(AA20:AA25,">0")+SUMIF(AA15,">0") -> 0 | AB41: =SUMIF(AC20:AC25,">0")+SUMIF(AC15,">0") -> 0 | AD41: =SUMIF(AE20:AE25,">0")+SUMIF(AE15,">0") -> 0 | AF41: =SUMIF(AG20:AG25,">0")+SUMIF(AG15,">0") -> 0
D42: % Cumplimiento mensual | J42: =IF(J40>0,J41/J40,IF(J40=0,"N,A")) -> 1 | L42: =IF(L40>0,L41/L40,IF(L40=0,"N,A")) -> 1 | N42: =IF(N40>0,N41/N40,IF(N40=0,"N,A")) -> 1 | P42: =IF(P40>0,P41/P40,IF(P40=0,"N,A")) -> 1 | R42: =IF(R40>0,R41/R40,IF(R40=0,"N,A")) -> 1 | T42: =IF(T40>0,T41/T40,IF(T40=0,"N,A")) -> 1 | V42: =IF(V40>0,V41/V40,IF(V40=0,"N,A")) -> 1 | X42: =IF(X40>0,X41/X40,IF(X40=0,"N,A")) -> N,A | Z42: =IF(Z40>0,Z41/Z40,IF(Z40=0,"N,A")) -> N,A | AB42: =IF(AB40>0,AB41/AB40,IF(AB40=0,"N,A")) -> N,A | AD42: =IF(AD40>0,AD41/AD40,IF(AD40=0,"N,A")) -> N,A | AF42: =IF(AF40>0,AF41/AF40,IF(AF40=0,"N,A")) -> N,A
...

Sheet MATRIZ POR CARGO
B1: PROGRAMA DE CAPACITACIÓN Y ENTRENAMIENTO ANUAL
B2: Fecha: 24/05/2023 Versión: 14 HSEQ-PRG-10
A3: CARGO PROPUESTO Y/O ROL | B3: PROYECTO | C3: PROCESO | D3: =CRONOGRAMA!A10 -> 1 | E3: =CRONOGRAMA!A11 -> 2 | F3: =CRONOGRAMA!A12 -> 3 | G3: =CRONOGRAMA!A13 -> 4 | H3: =CRONOGRAMA!A14 -> 5 | I3: =CRONOGRAMA!A15 -> 6 | J3: 7 | K3: =CRONOGRAMA!A17 -> 8 | L3: =CRONOGRAMA!A18 -> 9 | M3: =CRONOGRAMA!A19 -> 10 | N3: =CRONOGRAMA!A20 -> 11 | O3: =CRONOGRAMA!A21 -> 12 | P3: =CRONOGRAMA!A22 -> 13 | Q3: =CRONOGRAMA!A23 -> 14 | R3: =CRONOGRAMA!A24 -> 15
